Workbook

Sheet Matriz Ckeck LIst
C3: MATRIZ PARA COMPROBACIÓN REQUERIMIENTOS DE CALIDAD DE PROYECTO ACADEMICO
D5: SISTEMA: | E5: SISTEMA WEB DE GESTION DE EXPENSAS DEL CONJUNTO LA PRIMAVERA
B7: Nº | C7: CRITERIOS DE CALIDAD (Documento/Requerimientos) | E7: Status Nivel de Acuerdo | F7: CU-01: Administrar Sistema | I7: CU-1.1: Iniciar Sesión | K7: CU-1.2: Recuperar Contraseña
B9: 1 | C9: Agreed | E9: OK | F9: Es fundamental para el control de seguridad solicitado por el Administrador. | G9: OK | I9: Validado por el equipo de ingeniería de requisitos (Obando, Leiton, Gualotuña). | J9: OK | K9: Reduce la carga administrativa de resetear claves manualmente.
B10: 2 | C10: Ranked | E10: OK | F10: Clasificado como Must Have (M) en tu matriz MoSCoW. | G10: OK | I10: Prioridad crítica; sin esto no hay operación. | J10: OK | K10: Prioridad Must Have para evitar el bloqueo de usuarios.
B11: 3 | C11: Unambiguos | E11: OK | F11: Define claramente que gestiona acceso, autenticación y perfiles. | G11: NOK | I11: No se especifica si el bloqueo de cuenta es por IP o por ID de usuario, lo que genera ambigüedad en la política de seguridad. | J11: OK | K11: Define que el código es de 6 dígitos y dura 10 minutos.
B12: 4 | C12: Valid and up-to date | E12: OK | F12: Fecha de vigencia: 18 de enero de 2026. | G12: OK | I12: Incluye reglas modernas como encriptación y expiración de sesión. | J12: OK | K12: Sigue estándares actuales de seguridad (tokens temporales).
B13: 5 | C13: Correct | E13: OK | F13: Cubre la necesidad de jerarquía entre Administrador y Copropietario. | G13: OK | I13: El flujo normal (pasos 1-6) sigue la lógica estándar de autenticación. | J13: OK | K13: El proceso de validación vía correo electrónico es el correcto para este sistema.
B14: 6 | C14: Consisten | E14: OK | F14: No contradice otros requisitos; es la base de la seguridad. | G14: OK | I14: Se alinea con el RNF-01 (bcrypt y bloqueo de cuenta). | J14: NOK | K14: Existe una inconsistencia sobre el estado de las sesiones activas en otros dispositivos al momento de cambiar la contraseña.
B15: 7 | C15: Verifiable | E15: OK | F15: Se verifica mediante pruebas de caja negra (login exitoso/fallido). | G15: NOK | I15: El criterio de "bloqueo de 15 min" no es verificable sin definir si el contador se reinicia ante cada intento fallido adicional durante el bloqueo. | J15: OK | K15: Se puede verificar enviando el correo y validando el código en el sistema.
B16: 8 | C16: Realizable | E16: OK | F16: El uso de sesiones y perfiles es estándar en desarrollo web. | G16: OK | I16: Cambia a OK: Factible mediante el uso de bases de datos y manejo de sesiones. | J16: NOK | K16: La factibilidad técnica depende de un servicio SMTP externo cuya latencia no ha sido considerada en los tiempos de respuesta del RNF-05.
B17: 9 | C17: Traceable | E17: OK | F17: ID: RF-01, vinculado a los sub-procesos 1.1, 1.2 y 1.3. | G17: OK | I17: ID: RF-1.1. | J17: OK | K17: ID: RF-1.2.
B18: 10 | C18: Complete | E18: NOK | F18: Describe el propósito, actores y la regla de "mínimo un Administrador". | G18: OK | I18: Tiene precondiciones, postcondiciones y manejo de excepciones (flujo alterno). | J18: NOK | K18: El flujo no describe qué sucede si el usuario solicita un nuevo código antes de que expire el anterior (solapamiento de tokens).
B19: 11 | C19: Understandability | E19: OK | F19: No define el flujo de "Cierre de Sesión" (Logout), dejando incompleto el ciclo de vida de la administración de acceso. | G19: OK | I19: Detalla el proceso de validación paso a paso. | J19: OK | K19: Explica claramente la interacción usuario-sistema-correo.

Sheet MODELO LISTA DE COMPROBACION - 
B1: SISTEMA: | C1: SISTEMA WEB DE GESTION DE EXPENSAS DEL CONJUNTO LA PRIMAVERA
B2: FECHA: | C2: 46126
B3: AUTOR: | C3: Jose Leiton
B4: REQUERIMIENTOS EVALUADOS : | C4: CU-01
A6: CONTENIDO
A7: No. | B7: Pregunta | C7: SI | D7: NO
A8: 1 | B8: Todos los requerimientos relevantes se han documentado? | C8: X
A9: 2 | B9: Se han implementado las funciones requeridas? | C9: X
A10: 3 | B10: Existe algún mecanismo que permita seguir el impacto de dicho requerimiento a lo largo del resto de las actividades del ciclo productivo.? | C10: X
A11: 4 | B11: El origen de cada requerimento individual está claro ? | C11: X
A12: 5 | B12: Que tan facil es devolverse a los requerimientos? | C12: X
A13: 6 | B13: Los requerimientos reflejan las necesidades y deseos del cliente? | C13: X
A14: 7 | B14: No hay contradicciones entre los requerimientos? | C14: X
A15: 8 | B15: El requerimiento que se esta especificando contribuye a alcanzar un objetivo definido ? | C15: X
A16: 9 | B16: Existe un proceso acotado (en plazo y presupuesto) que permita determinar que el sistema construido satisface lo descrito en el propio requerimiento? | D16: X
A17: SUMATORIA: | C17: =COUNTA('MODELO LISTA DE COMPROBACION - '!$C$8:$C$16) -> 8 | D17: =COUNTA('MODELO LISTA DE COMPROBACION - '!$D$8:$D$16) -> 1
A18: PORCENTAJE : | C18: =C17/9 -> 0.88888889 | D18: =D17/9 -> 0.11111111
A20: DOCUMENTACIÓN
A21: No. | B21: Pregunta | C21: SI | D21: NO
A22: 1 | B22: Aplica un estandar para la documetación de requerimiento? | C22: X
A23: 2 | B23: Cumple con la estructura definida por el estandar? | C23: X
A24: 3 | B24: Utiliza un Glosario de términos normalizado? | C24: X
A25: 4 | B25: Los requerimientos Funcionales estan sujetos a una única interpretación? | C25: X
A26: 5 | B26: El modelo aplicado cumple con la sintaxis? | C26: X
A27: SUMATORIA: | C27: =COUNTA('MODELO LISTA DE COMPROBACION - '!$C$22:$C$26) -> 5 | D27: =COUNTA('MODELO LISTA DE COMPROBACION - '!$D$22:$D$26) -> 0
A28: PORCENTAJE : | C28: =C27/5 -> 1 | D28: =D27/5 -> 0
A30: NIVEL DE ACUERDO
A31: No. | B31: Pregunta | C31: SI | D31: NO
A32: 1 | B32: Todos los requerimientos han sido acordados con todos los interesados? | C32: X
A33: 2 | B33: Todos los requerimientos modificados han sido acordados por todos los implicados? | C33: X
A34: 3 | B34: Han sido resueltos todos los conflictos conocidos respectos de los requerimientos? | C34: X
A35: SUMATORIA: | C35: =COUNTA('MODELO LISTA DE COMPROBACION - '!$C$32:$C$34) -> 3 | D35: =COUNTA('MODELO LISTA DE COMPROBACION - '!$D$32:$D$34) -> 0
A36: PORCENTAJE : | C36: =C35/3 -> 1 | D36: =D35/3 -> 0
A40: RESUMEN
B41: CONTENIDO | C41: 89
B42: DOCUMENTACIÓN | C42: 100
B43: NIVEL DE ACUERDO | C43: 100
B47: AUTOR: Stiven Díaz
B48: REQUERIMIENTOS EVALUADOS : | C48: CU-1.1
A50: CONTENIDO
...

Sheet RECOMENDACIONES - CU001.3
A1: PREGUNTA | B1: RECOMENDACIÓN
A2: ¿Se ha definido el manejo de sesiones concurrentes para un mismo usuario? | B2: Especificar en la documentación si un Administrador o Copropietario puede tener la sesión abierta en varios dispositivos a la vez, o si el inicio de una nueva sesión debe cerrar automáticamente la anterior para mitigar riesgos de seguridad.
A3: ¿Existe un protocolo de seguridad para el envío del código de recuperación de 6 dígitos? | B3: Asegurar que el código de verificación (RF-1.2) no se envíe en texto plano sin cifrado TLS en el correo, y definir un límite de reintentos para ingresar el código antes de invalidar el token actual, evitando ataques de fuerza bruta al código de 6 dígitos.
A4: ¿Se ha contemplado la persistencia de la auditoría en la gestión de perfiles (RF-01)? | B4: Implementar un log o historial de cambios de privilegios. Si un Administrador promueve a un Copropietario, debe quedar registrado quién hizo el cambio, en qué fecha y bajo qué justificación, para mantener la trazabilidad que exige el RNF-02.
A5: ¿El flujo de "Recuperar Contraseña" incluye la validación de contraseñas anteriores? | B5: Por seguridad, el sistema no debería permitir que la "nueva contraseña" sea igual a la anterior. Se recomienda añadir una regla de negocio que verifique el historial de las últimas 3 contraseñas para forzar una renovación real.
A6: ¿Se han definido los estados visuales de los formularios en la interfaz (RNF-06)? | B6: Diseñar los estados de error y éxito de los campos en tiempo real (bordes rojos para errores, verdes para aciertos). Esto garantiza que el usuario sepa por qué no puede avanzar en el "Iniciar Sesión" sin esperar a que cargue la página.
A7: ¿Qué sucede si el servicio de correo electrónico (SMTP) no está disponible durante la recuperación? | B7: Definir una excepción clara en el RF-1.2 que indique al usuario: "Servicio de correo temporalmente fuera de línea, intente más tarde", evitando que el sistema se quede "pensando" o muestre un error técnico (500) que confunda al copropietario.
A10: CU - 1.1
A11: PREGUNTA | B11: RECOMENDACIÓN
A12: ¿Cómo avisa el sistema cuando la sesión caduca? | B12: Los comentarios indican que la sesión expira a las 2 horas. Se recomienda detallar en el flujo que el sistema debe devolver al usuario a la pantalla de inicio mostrando un mensaje claro: "Su sesión ha expirado por inactividad. Ingrese nuevamente"
A13: ¿El usuario distingue entre mayúsculas y minúsculas? | B13: Para evitar bloqueos tontos si el copropietario escribe "CASA15" en lugar de "casa15", se recomienda especificar en el paso 2 del flujo normal que el sistema transforma todo a minúsculas antes de validar (case-insensitive).
A14: Cuándo se reinicia el contador de intentos fallidos? | B14: El sistema bloquea la cuenta al tercer intento malo. Se recomienda añadir una nota que aclare que si el usuario se equivoca 2 veces, pero a la tercera ingresa correctamente, el contador de errores vuelve a cero automáticamente.
A15: ¿Qué pasa visualmente si deja campos vacíos? | B15: Alineado con el RNF-06 de usabilidad , se recomienda indicar en el paso 2 que si el usuario no pone la clave, el campo se marque en rojo advirtiendo el error inmediatamente, sin tener que recargar la página
A19: CU-1.2
A20: PREGUNTA | B20: RECOMENDACIÓN
A21: ¿Qué pasa con las sesiones abiertas en otros equipos tras cambiar la clave? | B21: Indicar en la postcondición que, al cambiar la contraseña con éxito, el sistema cierra automáticamente la sesión en cualquier otro dispositivo activo (móvil, PC) por seguridad.
A22: ¿Qué ocurre si el correo tarda en enviarse por culpa del servidor? | B22: Especificar que el sistema debe mostrar un estado de "Enviando..." y, si el correo falla, mostrar un mensaje amigable como "El servicio de correo está tardando, intente más tarde", para justificar los tiempos del RNF-05
A23: ¿El sistema anula el código anterior si el usuario se desespera y pide otro? | B23: Añadir en el flujo normal que si el usuario solicita un nuevo código antes de los 10 minutos, el código anterior caduca inmediatamente para evitar confusiones de "solapamiento".
A24: ¿Se unificaron los identificadores en todo el documento? | B24: Corregir el ID en la Matriz de Priorización, ya que actualmente figura como "RF-02" cuando pertenece a "RF-1.2". Esto arregla inmediatamente la trazabilidad.
